<?xml version="1.0" ?>
<robot name="MNP">
	<link name="world"/>
	<link name="base">
		<visual>
			<origin xyz="0 0 0.05" rpy="1.57 0 0"/>
			<geometry>
				<cylinder length="0.1" radius="0.05"/>
			</geometry>
		</visual>
		<collision>
			<origin xyz="0 0 0.05" rpy="1.57 0 0"/>
			<geometry>
				<cylinder length="0.1" radius="0.05"/>
			</geometry>
		</collision>
		<inertial>
			<origin xyz="0 0 0.05" rpy="1.57 0 0"/>
			<mass value="0.5"/>
			<inertia ixx="0.00041666666666666675" iyy="0" izz="0.00041666666666666675" ixy="0" iyz="0" ixz="0"/>
		</inertial>
	</link>
	<link name="lower_arm">
		<visual>
			<origin xyz="0 0 0.3" rpy="0 0 0"/>
			<geometry>
				<box size="0.1 0.05 0.5"/>
			</geometry>
		</visual>
		<collision>
			<origin xyz="0 0 0.3" rpy="0 0 0"/>
			<geometry>
				<box size="0.1 0.05 0.5"/>
			</geometry>
		</collision>
		<inertial>
			<origin xyz="0 0 0.3" rpy="0 0 0"/>
			<mass value="0.5"/>
			<inertia ixx="0.010520833333333333" iyy="0.010833333333333334" izz="0.0005208333333333334" ixy="0" iyz="0" ixz="0"/>
		</inertial>
	</link>
	<link name="upper_arm">
		<visual>
			<origin xyz="0 0 0.3" rpy="0 0 0"/>
			<geometry>
				<box size="0.1 0.05 0.5"/>
			</geometry>
		</visual>
		<collision>
			<origin xyz="0 0 0.3" rpy="0 0 0"/>
			<geometry>
				<box size="0.1 0.05 0.5"/>
			</geometry>
		</collision>
		<inertial>
			<origin xyz="0 0 0.3" rpy="0 0 0"/>
			<mass value="0.5"/>
			<inertia ixx="0.010520833333333333" iyy="0.010833333333333334" izz="0.0005208333333333334" ixy="0" iyz="0" ixz="0"/>
		</inertial>
	</link>
	<joint name="anchor" type="fixed">
		<parent link="world"/>
		<child link="base"/>
		<origin xyz="0 0 0" rpy="0 0 0"/>
		<axis xyz="0 0 0"/>
	</joint>
	<joint name="base_jnt" type="continuous">
		<parent link="base"/>
		<child link="lower_arm"/>
		<origin xyz="0 0 0.05" rpy="0 0 0"/>
		<axis xyz="0 1 0"/>
	</joint>
	<joint name="elbow_jnt" type="continuous">
		<parent link="lower_arm"/>
		<child link="upper_arm"/>
		<origin xyz="0 0 0.6" rpy="0 0 0"/>
		<axis xyz="0 1 0"/>
	</joint>
</robot>
